RPC_ERROR
Odoo Server Error
Traceback (most recent call last):
  File "/usr/lib/python3/dist-packages/odoo/tools/cache.py", line 99, in lookup
    r = d[key]
  File "<decorator-gen-5>", line 2, in __getitem__
  File "/usr/lib/python3/dist-packages/odoo/tools/func.py", line 87, in locked
    return func(inst, *args, **kwargs)
  File "/usr/lib/python3/dist-packages/odoo/tools/lru.py", line 34, in __getitem__
    a = self.d[obj]
KeyError: ('ir.model.data', <function IrModelData._xmlid_lookup at 0x7f08f63d8af0>, 'gimnasio_casa.gim_clase_action')

During handling of the above exception, another exception occurred:

Traceback (most recent call last):
  File "/usr/lib/python3/dist-packages/odoo/tools/convert.py", line 556, in _tag_root
    f(rec)
  File "/usr/lib/python3/dist-packages/odoo/tools/convert.py", line 312, in _tag_menuitem
    act = self.env.ref(a_action).sudo()
  File "/usr/lib/python3/dist-packages/odoo/api.py", line 580, in ref
    res_model, res_id = self['ir.model.data']._xmlid_to_res_model_res_id(
  File "/usr/lib/python3/dist-packages/odoo/addons/base/models/ir_model.py", line 2205, in _xmlid_to_res_model_res_id
    return self._xmlid_lookup(xmlid)
  File "<decorator-gen-43>", line 2, in _xmlid_lookup
  File "/usr/lib/python3/dist-packages/odoo/tools/cache.py", line 104, in lookup
    value = d[key] = self.method(*args, **kwargs)
  File "/usr/lib/python3/dist-packages/odoo/addons/base/models/ir_model.py", line 2198, in _xmlid_lookup
    raise ValueError('External ID not found in the system: %s' % xmlid)
ValueError: External ID not found in the system: gimnasio_casa.gim_clase_action

The above exception was the direct cause of the following exception:

Traceback (most recent call last):
  File "/usr/lib/python3/dist-packages/odoo/http.py", line 1788, in _serve_db
    return service_model.retrying(self._serve_ir_http, self.env)
  File "/usr/lib/python3/dist-packages/odoo/service/model.py", line 133, in retrying
    result = func()
  File "/usr/lib/python3/dist-packages/odoo/http.py", line 1816, in _serve_ir_http
    response = self.dispatcher.dispatch(rule.endpoint, args)
  File "/usr/lib/python3/dist-packages/odoo/http.py", line 2020, in dispatch
    result = self.request.registry['ir.http']._dispatch(endpoint)
  File "/usr/lib/python3/dist-packages/odoo/addons/base/models/ir_http.py", line 221, in _dispatch
    result = endpoint(**request.params)
  File "/usr/lib/python3/dist-packages/odoo/http.py", line 757, in route_wrapper
    result = endpoint(self, *args, **params_ok)
  File "/usr/lib/python3/dist-packages/odoo/addons/web/controllers/dataset.py", line 28, in call_button
    action = self._call_kw(model, method, args, kwargs)
  File "/usr/lib/python3/dist-packages/odoo/addons/web/controllers/dataset.py", line 20, in _call_kw
    return call_kw(request.env[model], method, args, kwargs)
  File "/usr/lib/python3/dist-packages/odoo/api.py", line 468, in call_kw
    result = _call_kw_multi(method, model, args, kwargs)
  File "/usr/lib/python3/dist-packages/odoo/api.py", line 453, in _call_kw_multi
    result = method(recs, *args, **kwargs)
  File "<decorator-gen-83>", line 2, in button_immediate_upgrade
  File "/usr/lib/python3/dist-packages/odoo/addons/base/models/ir_module.py", line 75, in check_and_log
    return method(self, *args, **kwargs)
  File "/usr/lib/python3/dist-packages/odoo/addons/base/models/ir_module.py", line 660, in button_immediate_upgrade
    return self._button_immediate_function(self.env.registry[self._name].button_upgrade)
  File "/usr/lib/python3/dist-packages/odoo/addons/base/models/ir_module.py", line 593, in _button_immediate_function
    registry = modules.registry.Registry.new(self._cr.dbname, update_module=True)
  File "<decorator-gen-16>", line 2, in new
  File "/usr/lib/python3/dist-packages/odoo/tools/func.py", line 87, in locked
    return func(inst, *args, **kwargs)
  File "/usr/lib/python3/dist-packages/odoo/modules/registry.py", line 110, in new
    odoo.modules.load_modules(registry, force_demo, status, update_module)
  File "/usr/lib/python3/dist-packages/odoo/modules/loading.py", line 477, in load_modules
    processed_modules += load_marked_modules(env, graph,
  File "/usr/lib/python3/dist-packages/odoo/modules/loading.py", line 365, in load_marked_modules
    loaded, processed = load_module_graph(
  File "/usr/lib/python3/dist-packages/odoo/modules/loading.py", line 228, in load_module_graph
    load_data(env, idref, mode, kind='data', package=package)
  File "/usr/lib/python3/dist-packages/odoo/modules/loading.py", line 72, in load_data
    tools.convert_file(env, package.name, filename, idref, mode, noupdate, kind)
  File "/usr/lib/python3/dist-packages/odoo/tools/convert.py", line 627, in convert_file
    convert_xml_import(env, module, fp, idref, mode, noupdate)
  File "/usr/lib/python3/dist-packages/odoo/tools/convert.py", line 693, in convert_xml_import
    obj.parse(doc.getroot())
  File "/usr/lib/python3/dist-packages/odoo/tools/convert.py", line 613, in parse
    self._tag_root(de)
  File "/usr/lib/python3/dist-packages/odoo/tools/convert.py", line 569, in _tag_root
    raise ParseError('while parsing %s:%s, somewhere inside\n%s' % (
odoo.tools.convert.ParseError: while parsing /mnt/extra-addons/gimnasio_casa/views/gim_menus.xml:11, somewhere inside
<menuitem id="gim_clase_menu" parent="gim_menu" action="gim_clase_action" name="Clase" sequence="20"/>

The above server error caused the following client error:
RPC_ERROR: Odoo Server Error
    RPC_ERROR
        at makeErrorFromResponse (http://localhost:8069/web/assets/dc063cd/web.assets_web.min.js:2929:163)
        at XMLHttpRequest.<anonymous> (http://localhost:8069/web/assets/dc063cd/web.assets_web.min.js:2933:13)